<?xml version="1.0" encoding="utf-8"?>
<robot xmlns:xacro="http://www.ros.org/wiki/xacro" name="triphibious_drone">
 <!-- Material definitions -->
  <material name="golden_yellow">
    <color rgba="1.0 0.84 0.0 1.0"/>
  </material>
  <material name="red">
    <color rgba="1.0 0.0 0.0 1.0"/>
  </material>
  <material name="blue">
    <color rgba="0.0 0.0 1.0 1.0"/>
  </material>
  <material name="green">
    <color rgba="0.0 1.0 0.0 1.0"/>
  </material>

  <link name="base_link"> 
    <inertial>
      <origin xyz="0 0 0" rpy="0 0 0"/>
      <mass value="2.000"/>
      <inertia ixx="0.03" ixy="0" ixz="0" iyy="0.055" iyz="0" izz="0.03"/></inertial>
      <visual>
        <origin xyz="0.000000 0.000000 0.000000" rpy="0 0 0"/>
        <geometry>
          <mesh filename="file://$(find triphibious_robot)/meshes_drone/base_main.stl" scale="0.001 0.001 0.001"/>
        </geometry>
      <material name="red"/>
      </visual>
        <collision><origin xyz="0.000000 0.000000 0.000000" rpy="0 0 0"/><geometry><mesh filename="file://$(find triphibious_robot)/meshes_drone/base_main.stl" scale="0.001 0.001 0.001"/></geometry></collision>
  </link>


  <link name="sphere_link"> 
    <inertial><origin xyz="0 0 0" rpy="0 0 0"/><mass value="0.800"/><inertia ixx="0.001" ixy="0" ixz="0" iyy="0.001" iyz="0" izz="0.001"/></inertial>
        <visual><origin xyz="0.000000 0.000000 0.000000" rpy="0 0 0"/><geometry><mesh filename="file://$(find triphibious_robot)/meshes_drone/sphere_from_step.stl" scale="0.001 0.001 0.001"/></geometry> <material name="golden_yellow"/></visual>
        <collision><origin xyz="0.000000 0.000000 0.000000" rpy="0 0 0"/><geometry><mesh filename="file://$(find triphibious_robot)/meshes_drone/sphere_from_step.stl" scale="0.001 0.001 0.001"/></geometry></collision>
  </link>


  <joint name="sphere_joint" type="continuous"> 
    <parent link="base_link"/>
    <child link="sphere_link"/>
    <origin xyz="0.000000 0.000000 0.010000" rpy="0 0 0"/>
    <axis xyz="0 1 0"/>
    <limit effort="2.0" velocity="3.0"/>
  <dynamics damping="0.2" friction="0.05"/>
  </joint>


    <link name="leg_1_shell_link"> 
        <inertial><origin xyz="0 0 0" rpy="0 0 0"/><mass value="0.030"/><inertia ixx="0.0001" ixy="0" ixz="0" iyy="0.0001" iyz="0" izz="0.0001"/></inertial>
        <visual><origin xyz="0 0 -0.025000" rpy="0 0 0"/><geometry><cylinder radius="0.016000" length="0.050000"/></geometry> <material name="blue"/></visual>
        <collision><origin xyz="0 0 -0.025000" rpy="0 0 0"/><geometry><cylinder radius="0.016000" length="0.050000"/></geometry></collision>
    </link>


  <joint name="leg_1_shell_fixed" type="fixed"> 
    <parent link="base_link"/>
    <child link="leg_1_shell_link"/>
    <origin xyz="0.068666 -0.075738 -0.005000" rpy="0 0 0"/>
  </joint>


  <link name="leg_1_link"> 
    <inertial><origin xyz="0 0 0" rpy="0 0 0"/><mass value="0.250"/><inertia ixx="0.001" ixy="0" ixz="0" iyy="0.001" iyz="0" izz="0.001"/></inertial>
        <visual><origin xyz="0.000000 0.000000 -0.042500" rpy="0 0 0"/><geometry><mesh filename="file://$(find triphibious_robot)/meshes_drone/leg_1.stl" scale="0.001 0.001 0.001"/></geometry> <material name="blue"/></visual>
        <collision><origin xyz="0.000000 0.000000 -0.042500" rpy="0 0 0"/><geometry><mesh filename="file://$(find triphibious_robot)/meshes_drone/leg_1.stl" scale="0.001 0.001 0.001"/></geometry></collision>
  </link>


  <joint name="leg_1_joint" type="prismatic"> 
    <parent link="leg_1_shell_link"/>
    <child link="leg_1_link"/>
    <origin xyz="0.000000 0.000000 0.000000" rpy="0 0 0"/>
    <axis xyz="0 0 1"/>
    <limit lower="0.0" upper="0.04" effort="300.0" velocity="0.2"/>
  </joint>


    <link name="leg_2_shell_link"> 
        <inertial><origin xyz="0 0 0" rpy="0 0 0"/><mass value="0.030"/><inertia ixx="0.0001" ixy="0" ixz="0" iyy="0.0001" iyz="0" izz="0.0001"/></inertial>
        <visual><origin xyz="0 0 -0.025000" rpy="0 0 0"/><geometry><cylinder radius="0.016000" length="0.050000"/></geometry> <material name="blue"/></visual>
        <collision><origin xyz="0 0 -0.025000" rpy="0 0 0"/><geometry><cylinder radius="0.016000" length="0.050000"/></geometry></collision>
    </link>


  <joint name="leg_2_shell_fixed" type="fixed"> 
    <parent link="base_link"/>
    <child link="leg_2_shell_link"/>
    <origin xyz="-0.075738 0.068666 -0.005000" rpy="0 0 0"/>
  </joint>


  <link name="leg_2_link"> 
    <inertial><origin xyz="0 0 0" rpy="0 0 0"/><mass value="0.250"/><inertia ixx="0.001" ixy="0" ixz="0" iyy="0.001" iyz="0" izz="0.001"/></inertial>
        <visual><origin xyz="0.000000 0.000000 -0.042500" rpy="0 0 0"/><geometry><mesh filename="file://$(find triphibious_robot)/meshes_drone/leg_2.stl" scale="0.001 0.001 0.001"/></geometry> <material name="blue"/></visual>
        <collision><origin xyz="0.000000 0.000000 -0.042500" rpy="0 0 0"/><geometry><mesh filename="file://$(find triphibious_robot)/meshes_drone/leg_2.stl" scale="0.001 0.001 0.001"/></geometry></collision>
  </link>


  <joint name="leg_2_joint" type="prismatic"> 
    <parent link="leg_2_shell_link"/>
    <child link="leg_2_link"/>
    <origin xyz="0.000000 0.000000 0.000000" rpy="0 0 0"/>
    <axis xyz="0 0 1"/>
    <limit lower="0.0" upper="0.04" effort="300.0" velocity="0.2"/>
  </joint>


    <link name="leg_3_shell_link"> 
        <inertial><origin xyz="0 0 0" rpy="0 0 0"/><mass value="0.030"/><inertia ixx="0.0001" ixy="0" ixz="0" iyy="0.0001" iyz="0" izz="0.0001"/></inertial>
        <visual><origin xyz="0 0 -0.025000" rpy="0 0 0"/><geometry><cylinder radius="0.016000" length="0.050000"/></geometry> <material name="blue"/></visual>
        <collision><origin xyz="0 0 -0.025000" rpy="0 0 0"/><geometry><cylinder radius="0.016000" length="0.050000"/></geometry></collision>
    </link>


  <joint name="leg_3_shell_fixed" type="fixed"> 
    <parent link="base_link"/>
    <child link="leg_3_shell_link"/>
    <origin xyz="0.075738 0.068666 -0.005000" rpy="0 0 0"/>
  </joint>


  <link name="leg_3_link"> 
    <inertial><origin xyz="0 0 0" rpy="0 0 0"/><mass value="0.250"/><inertia ixx="0.001" ixy="0" ixz="0" iyy="0.001" iyz="0" izz="0.001"/></inertial>
        <visual><origin xyz="0.000000 0.000000 -0.042500" rpy="0 0 0"/><geometry><mesh filename="file://$(find triphibious_robot)/meshes_drone/leg_3.stl" scale="0.001 0.001 0.001"/></geometry> <material name="blue"/></visual>
        <collision><origin xyz="0.000000 0.000000 -0.042500" rpy="0 0 0"/><geometry><mesh filename="file://$(find triphibious_robot)/meshes_drone/leg_3.stl" scale="0.001 0.001 0.001"/></geometry></collision>
  </link>


  <joint name="leg_3_joint" type="prismatic"> 
    <parent link="leg_3_shell_link"/>
    <child link="leg_3_link"/>
    <origin xyz="0.000000 0.000000 0.000000" rpy="0 0 0"/>
    <axis xyz="0 0 1"/>
    <limit lower="0.0" upper="0.04" effort="300.0" velocity="0.2"/>
  </joint>


    <link name="leg_4_shell_link"> 
        <inertial><origin xyz="0 0 0" rpy="0 0 0"/><mass value="0.030"/><inertia ixx="0.0001" ixy="0" ixz="0" iyy="0.0001" iyz="0" izz="0.0001"/></inertial>
        <visual><origin xyz="0 0 -0.025000" rpy="0 0 0"/><geometry><cylinder radius="0.016000" length="0.050000"/></geometry> <material name="blue"/></visual>
        <collision><origin xyz="0 0 -0.025000" rpy="0 0 0"/><geometry><cylinder radius="0.016000" length="0.050000"/></geometry></collision>
    </link>


  <joint name="leg_4_shell_fixed" type="fixed"> 
    <parent link="base_link"/>
    <child link="leg_4_shell_link"/>
    <origin xyz="-0.075738 -0.068666 -0.005000" rpy="0 0 0"/>
  </joint>


  <link name="leg_4_link"> 
    <inertial><origin xyz="0 0 0" rpy="0 0 0"/><mass value="0.250"/><inertia ixx="0.001" ixy="0" ixz="0" iyy="0.001" iyz="0" izz="0.001"/></inertial>
        <visual><origin xyz="0.000000 0.000000 -0.042500" rpy="0 0 0"/><geometry><mesh filename="file://$(find triphibious_robot)/meshes_drone/leg_4.stl" scale="0.001 0.001 0.001"/></geometry> <material name="blue"/></visual>
        <collision><origin xyz="0.000000 0.000000 -0.042500" rpy="0 0 0"/><geometry><mesh filename="file://$(find triphibious_robot)/meshes_drone/leg_4.stl" scale="0.001 0.001 0.001"/></geometry></collision>
  </link>


  <joint name="leg_4_joint" type="prismatic"> 
    <parent link="leg_4_shell_link"/>
    <child link="leg_4_link"/>
    <origin xyz="0.000000 0.000000 0.000000" rpy="0 0 0"/>
    <axis xyz="0 0 1"/>
    <limit lower="0.0" upper="0.04" effort="300.0" velocity="0.2"/>
  </joint>


  <link name="prop_1_link"> 
    <inertial><origin xyz="0 0 0" rpy="0 0 0"/><mass value="0.050"/><inertia ixx="0.001" ixy="0" ixz="0" iyy="0.001" iyz="0" izz="0.001"/></inertial>
        <visual><origin xyz="0.000000 0.000000 0.000000" rpy="0 0 0"/><geometry><mesh filename="file://$(find triphibious_robot)/meshes_drone/prop_1.stl" scale="0.001 0.001 0.001"/> </geometry><material name="green"/></visual>
        <collision><origin xyz="0.000000 0.000000 0.000000" rpy="0 0 0"/><geometry><mesh filename="file://$(find triphibious_robot)/meshes_drone/prop_1.stl" scale="0.001 0.001 0.001"/></geometry></collision>
  </link>


  <joint name="prop_1_joint" type="continuous"> 
    <parent link="base_link"/>
    <child link="prop_1_link"/>
    <origin xyz="-0.176777 0.176777 0.045049" rpy="0 0 0"/>
    <axis xyz="0 0 1"/>
  </joint>


  <link name="prop_2_link"> 
    <inertial><origin xyz="0 0 0" rpy="0 0 0"/><mass value="0.050"/><inertia ixx="0.001" ixy="0" ixz="0" iyy="0.001" iyz="0" izz="0.001"/></inertial>
        <visual><origin xyz="0.000000 0.000000 0.000000" rpy="0 0 0"/><geometry><mesh filename="file://$(find triphibious_robot)/meshes_drone/prop_2.stl" scale="0.001 0.001 0.001"/> </geometry><material name="green"/></visual>
        <collision><origin xyz="0.000000 0.000000 0.000000" rpy="0 0 0"/><geometry><mesh filename="file://$(find triphibious_robot)/meshes_drone/prop_2.stl" scale="0.001 0.001 0.001"/></geometry></collision>
  </link>


  <joint name="prop_2_joint" type="continuous"> 
    <parent link="base_link"/>
    <child link="prop_2_link"/>
    <origin xyz="-0.176777 -0.176777 0.045049" rpy="0 0 0"/>
    <axis xyz="0 0 1"/>
  </joint>


  <link name="prop_3_link"> 
    <inertial><origin xyz="0 0 0" rpy="0 0 0"/><mass value="0.050"/><inertia ixx="0.001" ixy="0" ixz="0" iyy="0.001" iyz="0" izz="0.001"/></inertial>
        <visual><origin xyz="0.000000 0.000000 0.000000" rpy="0 0 0"/><geometry><mesh filename="file://$(find triphibious_robot)/meshes_drone/prop_3.stl" scale="0.001 0.001 0.001"/> </geometry><material name="green"/></visual>
        <collision><origin xyz="0.000000 0.000000 0.000000" rpy="0 0 0"/><geometry><mesh filename="file://$(find triphibious_robot)/meshes_drone/prop_3.stl" scale="0.001 0.001 0.001"/></geometry></collision>
  </link>


  <joint name="prop_3_joint" type="continuous"> 
    <parent link="base_link"/>
    <child link="prop_3_link"/>
    <origin xyz="0.176717 -0.176697 0.045549" rpy="0 0 0"/>
    <axis xyz="0 0 1"/>
  </joint>


  <link name="prop_4_link"> 
    <inertial><origin xyz="0 0 0" rpy="0 0 0"/><mass value="0.050"/><inertia ixx="0.001" ixy="0" ixz="0" iyy="0.001" iyz="0" izz="0.001"/></inertial>
        <visual><origin xyz="0.000000 0.000000 0.000000" rpy="0 0 0"/><geometry><mesh filename="file://$(find triphibious_robot)/meshes_drone/prop_4.stl" scale="0.001 0.001 0.001"/></geometry><material name="green"/></visual>
        <collision><origin xyz="0.000000 0.000000 0.000000" rpy="0 0 0"/><geometry><mesh filename="file://$(find triphibious_robot)/meshes_drone/prop_4.stl" scale="0.001 0.001 0.001"/></geometry></collision>
  </link>


  <joint name="prop_4_joint" type="continuous"> 
    <parent link="base_link"/>
    <child link="prop_4_link"/>
    <origin xyz="0.175845 0.175008 0.045549" rpy="0 0 0"/>
    <axis xyz="0 0 1"/>
  </joint>
   <ros2_control name="DroneUfoSystem" type="system">
    <hardware>
      <plugin>gz_ros2_control/GazeboSimSystem</plugin>
    </hardware>

    <!-- sphere -->
    <joint name="sphere_joint">
      <command_interface name="velocity"/>
      <state_interface name="position"/>
      <state_interface name="velocity"/>
    </joint>

    <!-- legs -->
    <joint name="leg_1_joint">
      <command_interface name="position"/>
      <state_interface name="position"/>
      <state_interface name="velocity"/>
    </joint>
    <joint name="leg_2_joint">
      <command_interface name="position"/>
      <state_interface name="position"/>
      <state_interface name="velocity"/>
    </joint>
    <joint name="leg_3_joint">
      <command_interface name="position"/>
      <state_interface name="position"/>
      <state_interface name="velocity"/>
    </joint>
    <joint name="leg_4_joint">
      <command_interface name="position"/>
      <state_interface name="position"/>
      <state_interface name="velocity"/>
    </joint>

  </ros2_control>

  <gazebo>
    <plugin filename="libgz_ros2_control-system.so" name="gz_ros2_control::GazeboSimROS2ControlPlugin">
      <parameters>/home/pavan/Downloads/SUTD/DesignScience/ds_ws/src/triphibious_robot/config/controllers.yaml</parameters>
    </plugin>
  </gazebo>
  <gazebo>
    <plugin filename="libgz-sim8-multicopter-motor-model-system.so" name="gz::sim::systems::MulticopterMotorModel">
      <robotNamespace>triphibious_robot</robotNamespace>
      <jointName>prop_1_joint</jointName>
      <linkName>prop_1_link</linkName>
      <turningDirection>ccw</turningDirection>
      <timeConstantUp>0.0125</timeConstantUp>
      <timeConstantDown>0.025</timeConstantDown>
      <maxRotVelocity>1200.0</maxRotVelocity>
      <motorConstant>2.5e-05</motorConstant>
      <momentConstant>0.016754</momentConstant>
      <commandSubTopic>gazebo/command/motor_speed</commandSubTopic>
      <actuator_number>0</actuator_number>
      <rotorDragCoefficient>8.06428e-05</rotorDragCoefficient>
      <rollingMomentCoefficient>1e-06</rollingMomentCoefficient>
      <motorSpeedPubTopic>motor_speed/0</motorSpeedPubTopic>
      <rotorVelocitySlowdownSim>10</rotorVelocitySlowdownSim>
      <motorType>velocity</motorType>
    </plugin>
    <plugin filename="libgz-sim8-multicopter-motor-model-system.so" name="gz::sim::systems::MulticopterMotorModel">
      <robotNamespace>triphibious_robot</robotNamespace>
      <jointName>prop_2_joint</jointName>
      <linkName>prop_2_link</linkName>
      <turningDirection>ccw</turningDirection>
      <timeConstantUp>0.0125</timeConstantUp>
      <timeConstantDown>0.025</timeConstantDown>
      <maxRotVelocity>1200.0</maxRotVelocity>
      <motorConstant>2.5e-05</motorConstant>
      <momentConstant>0.016754</momentConstant>
      <commandSubTopic>gazebo/command/motor_speed</commandSubTopic>
      <actuator_number>1</actuator_number>
      <rotorDragCoefficient>8.06428e-05</rotorDragCoefficient>
      <rollingMomentCoefficient>1e-06</rollingMomentCoefficient>
      <motorSpeedPubTopic>motor_speed/1</motorSpeedPubTopic>
      <rotorVelocitySlowdownSim>10</rotorVelocitySlowdownSim>
      <motorType>velocity</motorType>
    </plugin>
    <plugin filename="libgz-sim8-multicopter-motor-model-system.so" name="gz::sim::systems::MulticopterMotorModel">
      <robotNamespace>triphibious_robot</robotNamespace>
      <jointName>prop_3_joint</jointName>
      <linkName>prop_3_link</linkName>
      <turningDirection>ccw</turningDirection>
      <timeConstantUp>0.0125</timeConstantUp>
      <timeConstantDown>0.025</timeConstantDown>
      <maxRotVelocity>1200.0</maxRotVelocity>
      <motorConstant>2.5e-05</motorConstant>
      <momentConstant>0.016754</momentConstant>
      <commandSubTopic>gazebo/command/motor_speed</commandSubTopic>
      <actuator_number>2</actuator_number>
      <rotorDragCoefficient>8.06428e-05</rotorDragCoefficient>
      <rollingMomentCoefficient>1e-06</rollingMomentCoefficient>
      <motorSpeedPubTopic>motor_speed/2</motorSpeedPubTopic>
      <rotorVelocitySlowdownSim>10</rotorVelocitySlowdownSim>
      <motorType>velocity</motorType>
    </plugin>
    <plugin filename="libgz-sim8-multicopter-motor-model-system.so" name="gz::sim::systems::MulticopterMotorModel">
      <robotNamespace>triphibious_robot</robotNamespace>
      <jointName>prop_4_joint</jointName>
      <linkName>prop_4_link</linkName>
      <turningDirection>cw</turningDirection>
      <timeConstantUp>0.0125</timeConstantUp>
      <timeConstantDown>0.025</timeConstantDown>
      <maxRotVelocity>1200.0</maxRotVelocity>
      <motorConstant>2.5e-05</motorConstant>
      <momentConstant>0.016754</momentConstant>
      <commandSubTopic>gazebo/command/motor_speed</commandSubTopic>
      <actuator_number>3</actuator_number>
      <rotorDragCoefficient>8.06428e-05</rotorDragCoefficient>
      <rollingMomentCoefficient>1e-06</rollingMomentCoefficient>
      <motorSpeedPubTopic>motor_speed/3</motorSpeedPubTopic>
      <rotorVelocitySlowdownSim>10</rotorVelocitySlowdownSim>
      <motorType>velocity</motorType>
    </plugin>
  </gazebo>

  <gazebo>
    <plugin filename="libgz-sim8-multicopter-control-system.so" name="gz::sim::systems::MulticopterVelocityControl">
      <robotNamespace>triphibious_robot</robotNamespace>
      <commandSubTopic>gazebo/command/twist</commandSubTopic>
      <enableSubTopic>enable</enableSubTopic>
      <comLinkName>base_link</comLinkName>
      <velocityGain>6 6 10</velocityGain>
      <attitudeGain>4 4 2</attitudeGain>
      <angularRateGain>0.7 0.7 0.7</angularRateGain>
      <maximumLinearAcceleration>1 1 2</maximumLinearAcceleration>
      <maximumLinearVelocity>5 5 5</maximumLinearVelocity>
      <maximumAngularVelocity>3 3 3</maximumAngularVelocity>
      <rotorConfiguration>
        <rotor>
          <jointName>prop_1_joint</jointName>
          <forceConstant>2.5e-05</forceConstant>
          <momentConstant>1.6754e-2</momentConstant>
          <direction>1</direction>
        </rotor>
        <rotor>
          <jointName>prop_2_joint</jointName>
          <forceConstant>2.5e-05</forceConstant>
          <momentConstant>1.6754e-2</momentConstant>
          <direction>1</direction>
        </rotor>
        <rotor>
          <jointName>prop_3_joint</jointName>
          <forceConstant>2.5e-05</forceConstant>
          <momentConstant>1.6754e-2</momentConstant>
          <direction>-1</direction>
        </rotor>
        <rotor>
          <jointName>prop_4_joint</jointName>
          <forceConstant>2.5e-05</forceConstant>
          <momentConstant>1.6754e-2</momentConstant>
          <direction>-1</direction>
        </rotor>
      </rotorConfiguration>
    </plugin>
  </gazebo>

</robot>